FEFF.
======================================================================
ERROR: test_client_get_client_error (test_client.TestClient.test_client_get_client_error)
----------------------------------------------------------------------
Traceback (most recent call last):
  File "C:\Users\userrr\AppData\Local\Programs\Python\Python311\Lib\unittest\mock.py", line 1369, in patched
    return func(*newargs, **newkeywargs)
           ^^^^^^^^^^^^^^^^^^^^^^^^^^^^^
  File "D:\Documents\!грш\внит\test_client.py", line 153, in test_client_get_client_error
    self.assertRaises(ClientError,
  File "C:\Users\userrr\AppData\Local\Programs\Python\Python311\Lib\unittest\case.py", line 766, in assertRaises
    return context.handle('assertRaises', args, kwargs)
           ^^^^^^^^^^^^^^^^^^^^^^^^^^^^^^^^^^^^^^^^^^^^
  File "C:\Users\userrr\AppData\Local\Programs\Python\Python311\Lib\unittest\case.py", line 222, in handle
    raise TypeError('%s() arg 1 must be %s' %
TypeError: assertRaises() arg 1 must be an exception type or tuple of exception types

======================================================================
FAIL: test_client_get_all (test_client.TestClient.test_client_get_all)
----------------------------------------------------------------------
Traceback (most recent call last):
  File "C:\Users\userrr\AppData\Local\Programs\Python\Python311\Lib\unittest\mock.py", line 1369, in patched
    return func(*newargs, **newkeywargs)
           ^^^^^^^^^^^^^^^^^^^^^^^^^^^^^
  File "D:\Documents\!грш\внит\test_client.py", line 136, in test_client_get_all
    self.assertEqual(rsp, metrics_fixture)
AssertionError: b'ok\ntest 0.5 1\ntest 0.4 2\nload 301 3\n\n' != {'test': [(1, 0.5), (2, 0.4)], 'load': [(3, 301.0)]}

======================================================================
FAIL: test_client_get_key (test_client.TestClient.test_client_get_key)
----------------------------------------------------------------------
Traceback (most recent call last):
  File "C:\Users\userrr\AppData\Local\Programs\Python\Python311\Lib\unittest\mock.py", line 1369, in patched
    return func(*newargs, **newkeywargs)
           ^^^^^^^^^^^^^^^^^^^^^^^^^^^^^
  File "D:\Documents\!грш\внит\test_client.py", line 121, in test_client_get_key
    self.assertEqual(rsp, metrics_fixture)
AssertionError: b'ok\ntest 0.5 1\ntest 0.4 2\n\n' != {'test': [(1, 0.5), (2, 0.4)]}

======================================================================
FAIL: test_client_get_not_exists (test_client.TestClient.test_client_get_not_exists)
----------------------------------------------------------------------
Traceback (most recent call last):
  File "C:\Users\userrr\AppData\Local\Programs\Python\Python311\Lib\unittest\mock.py", line 1369, in patched
    return func(*newargs, **newkeywargs)
           ^^^^^^^^^^^^^^^^^^^^^^^^^^^^^
  File "D:\Documents\!грш\внит\test_client.py", line 147, in test_client_get_not_exists
    self.assertEqual({}, rsp, "check rsp eq {}")
AssertionError: {} != b'ok\n\n' : check rsp eq {}

----------------------------------------------------------------------
Ran 5 tests in 0.005s

FAILED (failures=3, errors=1)